Traceback (most recent call last):
  File "/home/ec2-user/venv_Grupo01/local/lib/python3.6/site-packages/django/db/backends/postgresql/base.py", line 20, in <module>
    import psycopg2 as Database
ModuleNotFoundError: No module named 'psycopg2'

During handling of the above exception, another exception occurred:

Traceback (most recent call last):
  File "/home/ec2-user/Grupo01/image_process.py", line 11, in <module>
    django.setup()
  File "/home/ec2-user/venv_Grupo01/local/lib/python3.6/site-packages/django/__init__.py", line 24, in setup
    apps.populate(settings.INSTALLED_APPS)
  File "/home/ec2-user/venv_Grupo01/local/lib/python3.6/site-packages/django/apps/registry.py", line 112, in populate
    app_config.import_models()
  File "/home/ec2-user/venv_Grupo01/local/lib/python3.6/site-packages/django/apps/config.py", line 198, in import_models
    self.models_module = import_module(models_module_name)
  File "/home/ec2-user/venv_Grupo01/lib64/python3.6/importlib/__init__.py", line 126, in import_module
    return _bootstrap._gcd_import(name[level:], package, level)
  File "<frozen importlib._bootstrap>", line 994, in _gcd_import
  File "<frozen importlib._bootstrap>", line 971, in _find_and_load
  File "<frozen importlib._bootstrap>", line 955, in _find_and_load_unlocked
  File "<frozen importlib._bootstrap>", line 665, in _load_unlocked
  File "<frozen importlib._bootstrap_external>", line 678, in exec_module
  File "<frozen importlib._bootstrap>", line 219, in _call_with_frames_removed
  File "/home/ec2-user/venv_Grupo01/local/lib/python3.6/site-packages/django/contrib/auth/models.py", line 2, in <module>
    from django.contrib.auth.base_user import AbstractBaseUser, BaseUserManager
  File "/home/ec2-user/venv_Grupo01/local/lib/python3.6/site-packages/django/contrib/auth/base_user.py", line 47, in <module>
    class AbstractBaseUser(models.Model):
  File "/home/ec2-user/venv_Grupo01/local/lib/python3.6/site-packages/django/db/models/base.py", line 101, in __new__
    new_class.add_to_class('_meta', Options(meta, app_label))
  File "/home/ec2-user/venv_Grupo01/local/lib/python3.6/site-packages/django/db/models/base.py", line 305, in add_to_class
    value.contribute_to_class(cls, name)
  File "/home/ec2-user/venv_Grupo01/local/lib/python3.6/site-packages/django/db/models/options.py", line 203, in contribute_to_class
    self.db_table = truncate_name(self.db_table, connection.ops.max_name_length())
  File "/home/ec2-user/venv_Grupo01/local/lib/python3.6/site-packages/django/db/__init__.py", line 33, in __getattr__
    return getattr(connections[DEFAULT_DB_ALIAS], item)
  File "/home/ec2-user/venv_Grupo01/local/lib/python3.6/site-packages/django/db/utils.py", line 202, in __getitem__
    backend = load_backend(db['ENGINE'])
  File "/home/ec2-user/venv_Grupo01/local/lib/python3.6/site-packages/django/db/utils.py", line 110, in load_backend
    return import_module('%s.base' % backend_name)
  File "/home/ec2-user/venv_Grupo01/lib64/python3.6/importlib/__init__.py", line 126, in import_module
    return _bootstrap._gcd_import(name[level:], package, level)
  File "/home/ec2-user/venv_Grupo01/local/lib/python3.6/site-packages/django/db/backends/postgresql/base.py", line 24, in <module>
    raise ImproperlyConfigured("Error loading psycopg2 module: %s" % e)
django.core.exceptions.ImproperlyConfigured: Error loading psycopg2 module: No module named 'psycopg2'
Traceback (most recent call last):
  File "/home/ec2-user/venv_Grupo01/local/lib/python3.6/site-packages/django/db/backends/postgresql/base.py", line 20, in <module>
    import psycopg2 as Database
ModuleNotFoundError: No module named 'psycopg2'

During handling of the above exception, another exception occurred:

Traceback (most recent call last):
  File "/home/ec2-user/Grupo01/image_process.py", line 11, in <module>
    django.setup()
  File "/home/ec2-user/venv_Grupo01/local/lib/python3.6/site-packages/django/__init__.py", line 24, in setup
    apps.populate(settings.INSTALLED_APPS)
  File "/home/ec2-user/venv_Grupo01/local/lib/python3.6/site-packages/django/apps/registry.py", line 112, in populate
    app_config.import_models()
  File "/home/ec2-user/venv_Grupo01/local/lib/python3.6/site-packages/django/apps/config.py", line 198, in import_models
    self.models_module = import_module(models_module_name)
  File "/home/ec2-user/venv_Grupo01/lib64/python3.6/importlib/__init__.py", line 126, in import_module
    return _bootstrap._gcd_import(name[level:], package, level)
  File "<frozen importlib._bootstrap>", line 994, in _gcd_import
  File "<frozen importlib._bootstrap>", line 971, in _find_and_load
  File "<frozen importlib._bootstrap>", line 955, in _find_and_load_unlocked
  File "<frozen importlib._bootstrap>", line 665, in _load_unlocked
  File "<frozen importlib._bootstrap_external>", line 678, in exec_module
  File "<frozen importlib._bootstrap>", line 219, in _call_with_frames_removed
  File "/home/ec2-user/venv_Grupo01/local/lib/python3.6/site-packages/django/contrib/auth/models.py", line 2, in <module>
    from django.contrib.auth.base_user import AbstractBaseUser, BaseUserManager
  File "/home/ec2-user/venv_Grupo01/local/lib/python3.6/site-packages/django/contrib/auth/base_user.py", line 47, in <module>
    class AbstractBaseUser(models.Model):
  File "/home/ec2-user/venv_Grupo01/local/lib/python3.6/site-packages/django/db/models/base.py", line 101, in __new__
    new_class.add_to_class('_meta', Options(meta, app_label))
  File "/home/ec2-user/venv_Grupo01/local/lib/python3.6/site-packages/django/db/models/base.py", line 305, in add_to_class
    value.contribute_to_class(cls, name)
  File "/home/ec2-user/venv_Grupo01/local/lib/python3.6/site-packages/django/db/models/options.py", line 203, in contribute_to_class
    self.db_table = truncate_name(self.db_table, connection.ops.max_name_length())
  File "/home/ec2-user/venv_Grupo01/local/lib/python3.6/site-packages/django/db/__init__.py", line 33, in __getattr__
    return getattr(connections[DEFAULT_DB_ALIAS], item)
  File "/home/ec2-user/venv_Grupo01/local/lib/python3.6/site-packages/django/db/utils.py", line 202, in __getitem__
    backend = load_backend(db['ENGINE'])
  File "/home/ec2-user/venv_Grupo01/local/lib/python3.6/site-packages/django/db/utils.py", line 110, in load_backend
    return import_module('%s.base' % backend_name)
  File "/home/ec2-user/venv_Grupo01/lib64/python3.6/importlib/__init__.py", line 126, in import_module
    return _bootstrap._gcd_import(name[level:], package, level)
  File "/home/ec2-user/venv_Grupo01/local/lib/python3.6/site-packages/django/db/backends/postgresql/base.py", line 24, in <module>
    raise ImproperlyConfigured("Error loading psycopg2 module: %s" % e)
django.core.exceptions.ImproperlyConfigured: Error loading psycopg2 module: No module named 'psycopg2'
Traceback (most recent call last):
  File "/home/ec2-user/venv_Grupo01/local/lib/python3.6/site-packages/django/db/backends/postgresql/base.py", line 20, in <module>
    import psycopg2 as Database
ModuleNotFoundError: No module named 'psycopg2'

During handling of the above exception, another exception occurred:

Traceback (most recent call last):
  File "/home/ec2-user/Grupo01/image_process.py", line 11, in <module>
    django.setup()
  File "/home/ec2-user/venv_Grupo01/local/lib/python3.6/site-packages/django/__init__.py", line 24, in setup
    apps.populate(settings.INSTALLED_APPS)
  File "/home/ec2-user/venv_Grupo01/local/lib/python3.6/site-packages/django/apps/registry.py", line 112, in populate
    app_config.import_models()
  File "/home/ec2-user/venv_Grupo01/local/lib/python3.6/site-packages/django/apps/config.py", line 198, in import_models
    self.models_module = import_module(models_module_name)
  File "/home/ec2-user/venv_Grupo01/lib64/python3.6/importlib/__init__.py", line 126, in import_module
    return _bootstrap._gcd_import(name[level:], package, level)
  File "<frozen importlib._bootstrap>", line 994, in _gcd_import
  File "<frozen importlib._bootstrap>", line 971, in _find_and_load
  File "<frozen importlib._bootstrap>", line 955, in _find_and_load_unlocked
  File "<frozen importlib._bootstrap>", line 665, in _load_unlocked
  File "<frozen importlib._bootstrap_external>", line 678, in exec_module
  File "<frozen importlib._bootstrap>", line 219, in _call_with_frames_removed
  File "/home/ec2-user/venv_Grupo01/local/lib/python3.6/site-packages/django/contrib/auth/models.py", line 2, in <module>
    from django.contrib.auth.base_user import AbstractBaseUser, BaseUserManager
  File "/home/ec2-user/venv_Grupo01/local/lib/python3.6/site-packages/django/contrib/auth/base_user.py", line 47, in <module>
    class AbstractBaseUser(models.Model):
  File "/home/ec2-user/venv_Grupo01/local/lib/python3.6/site-packages/django/db/models/base.py", line 101, in __new__
    new_class.add_to_class('_meta', Options(meta, app_label))
  File "/home/ec2-user/venv_Grupo01/local/lib/python3.6/site-packages/django/db/models/base.py", line 305, in add_to_class
    value.contribute_to_class(cls, name)
  File "/home/ec2-user/venv_Grupo01/local/lib/python3.6/site-packages/django/db/models/options.py", line 203, in contribute_to_class
    self.db_table = truncate_name(self.db_table, connection.ops.max_name_length())
  File "/home/ec2-user/venv_Grupo01/local/lib/python3.6/site-packages/django/db/__init__.py", line 33, in __getattr__
    return getattr(connections[DEFAULT_DB_ALIAS], item)
  File "/home/ec2-user/venv_Grupo01/local/lib/python3.6/site-packages/django/db/utils.py", line 202, in __getitem__
    backend = load_backend(db['ENGINE'])
  File "/home/ec2-user/venv_Grupo01/local/lib/python3.6/site-packages/django/db/utils.py", line 110, in load_backend
    return import_module('%s.base' % backend_name)
  File "/home/ec2-user/venv_Grupo01/lib64/python3.6/importlib/__init__.py", line 126, in import_module
    return _bootstrap._gcd_import(name[level:], package, level)
  File "/home/ec2-user/venv_Grupo01/local/lib/python3.6/site-packages/django/db/backends/postgresql/base.py", line 24, in <module>
    raise ImproperlyConfigured("Error loading psycopg2 module: %s" % e)
django.core.exceptions.ImproperlyConfigured: Error loading psycopg2 module: No module named 'psycopg2'
Traceback (most recent call last):
  File "/home/ec2-user/venv_Grupo01/local/lib/python3.6/site-packages/urllib3/connection.py", line 160, in _new_conn
    (self._dns_host, self.port), self.timeout, **extra_kw)
  File "/home/ec2-user/venv_Grupo01/local/lib/python3.6/site-packages/urllib3/util/connection.py", line 80, in create_connection
    raise err
  File "/home/ec2-user/venv_Grupo01/local/lib/python3.6/site-packages/urllib3/util/connection.py", line 70, in create_connection
    sock.connect(sa)
TimeoutError: [Errno 110] Connection timed out

During handling of the above exception, another exception occurred:

Traceback (most recent call last):
  File "/home/ec2-user/venv_Grupo01/local/lib/python3.6/site-packages/urllib3/connectionpool.py", line 603, in urlopen
    chunked=chunked)
  File "/home/ec2-user/venv_Grupo01/local/lib/python3.6/site-packages/urllib3/connectionpool.py", line 355, in _make_request
    conn.request(method, url, **httplib_request_kw)
  File "/usr/lib64/python3.6/http/client.py", line 1254, in request
    self._send_request(method, url, body, headers, encode_chunked)
  File "/usr/lib64/python3.6/http/client.py", line 1300, in _send_request
    self.endheaders(body, encode_chunked=encode_chunked)
  File "/usr/lib64/python3.6/http/client.py", line 1249, in endheaders
    self._send_output(message_body, encode_chunked=encode_chunked)
  File "/usr/lib64/python3.6/http/client.py", line 1036, in _send_output
    self.send(msg)
  File "/usr/lib64/python3.6/http/client.py", line 974, in send
    self.connect()
  File "/home/ec2-user/venv_Grupo01/local/lib/python3.6/site-packages/urllib3/connection.py", line 183, in connect
    conn = self._new_conn()
  File "/home/ec2-user/venv_Grupo01/local/lib/python3.6/site-packages/urllib3/connection.py", line 169, in _new_conn
    self, "Failed to establish a new connection: %s" % e)
urllib3.exceptions.NewConnectionError: <urllib3.connection.HTTPConnection object at 0x7fda3664edd8>: Failed to establish a new connection: [Errno 110] Connection timed out

During handling of the above exception, another exception occurred:

Traceback (most recent call last):
  File "/home/ec2-user/venv_Grupo01/local/lib/python3.6/site-packages/requests/adapters.py", line 449, in send
    timeout=timeout
  File "/home/ec2-user/venv_Grupo01/local/lib/python3.6/site-packages/urllib3/connectionpool.py", line 641, in urlopen
    _stacktrace=sys.exc_info()[2])
  File "/home/ec2-user/venv_Grupo01/local/lib/python3.6/site-packages/urllib3/util/retry.py", line 399, in increment
    raise MaxRetryError(_pool, url, error or ResponseError(cause))
urllib3.exceptions.MaxRetryError: HTTPConnectionPool(host='54.235.13.161', port=8000): Max retries exceeded with url: /disenos/ (Caused by NewConnectionError('<urllib3.connection.HTTPConnection object at 0x7fda3664edd8>: Failed to establish a new connection: [Errno 110] Connection timed out',))

During handling of the above exception, another exception occurred:

Traceback (most recent call last):
  File "/home/ec2-user/Grupo01/image_process.py", line 17, in <module>
    response = requests.get(url)
  File "/home/ec2-user/venv_Grupo01/local/lib/python3.6/site-packages/requests/api.py", line 75, in get
    return request('get', url, params=params, **kwargs)
  File "/home/ec2-user/venv_Grupo01/local/lib/python3.6/site-packages/requests/api.py", line 60, in request
    return session.request(method=method, url=url, **kwargs)
  File "/home/ec2-user/venv_Grupo01/local/lib/python3.6/site-packages/requests/sessions.py", line 533, in request
    resp = self.send(prep, **send_kwargs)
  File "/home/ec2-user/venv_Grupo01/local/lib/python3.6/site-packages/requests/sessions.py", line 646, in send
    r = adapter.send(request, **kwargs)
  File "/home/ec2-user/venv_Grupo01/local/lib/python3.6/site-packages/requests/adapters.py", line 516, in send
    raise ConnectionError(e, request=request)
requests.exceptions.ConnectionError: HTTPConnectionPool(host='54.235.13.161', port=8000): Max retries exceeded with url: /disenos/ (Caused by NewConnectionError('<urllib3.connection.HTTPConnection object at 0x7fda3664edd8>: Failed to establish a new connection: [Errno 110] Connection timed out',))
Traceback (most recent call last):
  File "/home/ec2-user/venv_Grupo01/local/lib/python3.6/site-packages/urllib3/connection.py", line 160, in _new_conn
    (self._dns_host, self.port), self.timeout, **extra_kw)
  File "/home/ec2-user/venv_Grupo01/local/lib/python3.6/site-packages/urllib3/util/connection.py", line 80, in create_connection
    raise err
  File "/home/ec2-user/venv_Grupo01/local/lib/python3.6/site-packages/urllib3/util/connection.py", line 70, in create_connection
    sock.connect(sa)
TimeoutError: [Errno 110] Connection timed out

During handling of the above exception, another exception occurred:

Traceback (most recent call last):
  File "/home/ec2-user/venv_Grupo01/local/lib/python3.6/site-packages/urllib3/connectionpool.py", line 603, in urlopen
    chunked=chunked)
  File "/home/ec2-user/venv_Grupo01/local/lib/python3.6/site-packages/urllib3/connectionpool.py", line 355, in _make_request
    conn.request(method, url, **httplib_request_kw)
  File "/usr/lib64/python3.6/http/client.py", line 1254, in request
    self._send_request(method, url, body, headers, encode_chunked)
  File "/usr/lib64/python3.6/http/client.py", line 1300, in _send_request
    self.endheaders(body, encode_chunked=encode_chunked)
  File "/usr/lib64/python3.6/http/client.py", line 1249, in endheaders
    self._send_output(message_body, encode_chunked=encode_chunked)
  File "/usr/lib64/python3.6/http/client.py", line 1036, in _send_output
    self.send(msg)
  File "/usr/lib64/python3.6/http/client.py", line 974, in send
    self.connect()
  File "/home/ec2-user/venv_Grupo01/local/lib/python3.6/site-packages/urllib3/connection.py", line 183, in connect
    conn = self._new_conn()
  File "/home/ec2-user/venv_Grupo01/local/lib/python3.6/site-packages/urllib3/connection.py", line 169, in _new_conn
    self, "Failed to establish a new connection: %s" % e)
urllib3.exceptions.NewConnectionError: <urllib3.connection.HTTPConnection object at 0x7f16a4e8cdd8>: Failed to establish a new connection: [Errno 110] Connection timed out

During handling of the above exception, another exception occurred:

Traceback (most recent call last):
  File "/home/ec2-user/venv_Grupo01/local/lib/python3.6/site-packages/requests/adapters.py", line 449, in send
    timeout=timeout
  File "/home/ec2-user/venv_Grupo01/local/lib/python3.6/site-packages/urllib3/connectionpool.py", line 641, in urlopen
    _stacktrace=sys.exc_info()[2])
  File "/home/ec2-user/venv_Grupo01/local/lib/python3.6/site-packages/urllib3/util/retry.py", line 399, in increment
    raise MaxRetryError(_pool, url, error or ResponseError(cause))
urllib3.exceptions.MaxRetryError: HTTPConnectionPool(host='54.235.13.161', port=8000): Max retries exceeded with url: /disenos/ (Caused by NewConnectionError('<urllib3.connection.HTTPConnection object at 0x7f16a4e8cdd8>: Failed to establish a new connection: [Errno 110] Connection timed out',))

During handling of the above exception, another exception occurred:

Traceback (most recent call last):
  File "/home/ec2-user/Grupo01/image_process.py", line 17, in <module>
    response = requests.get(url)
  File "/home/ec2-user/venv_Grupo01/local/lib/python3.6/site-packages/requests/api.py", line 75, in get
    return request('get', url, params=params, **kwargs)
  File "/home/ec2-user/venv_Grupo01/local/lib/python3.6/site-packages/requests/api.py", line 60, in request
    return session.request(method=method, url=url, **kwargs)
  File "/home/ec2-user/venv_Grupo01/local/lib/python3.6/site-packages/requests/sessions.py", line 533, in request
    resp = self.send(prep, **send_kwargs)
  File "/home/ec2-user/venv_Grupo01/local/lib/python3.6/site-packages/requests/sessions.py", line 646, in send
    r = adapter.send(request, **kwargs)
  File "/home/ec2-user/venv_Grupo01/local/lib/python3.6/site-packages/requests/adapters.py", line 516, in send
    raise ConnectionError(e, request=request)
requests.exceptions.ConnectionError: HTTPConnectionPool(host='54.235.13.161', port=8000): Max retries exceeded with url: /disenos/ (Caused by NewConnectionError('<urllib3.connection.HTTPConnection object at 0x7f16a4e8cdd8>: Failed to establish a new connection: [Errno 110] Connection timed out',))
Traceback (most recent call last):
  File "/home/ec2-user/venv_Grupo01/local/lib/python3.6/site-packages/urllib3/connection.py", line 160, in _new_conn
    (self._dns_host, self.port), self.timeout, **extra_kw)
  File "/home/ec2-user/venv_Grupo01/local/lib/python3.6/site-packages/urllib3/util/connection.py", line 80, in create_connection
    raise err
  File "/home/ec2-user/venv_Grupo01/local/lib/python3.6/site-packages/urllib3/util/connection.py", line 70, in create_connection
    sock.connect(sa)
TimeoutError: [Errno 110] Connection timed out

During handling of the above exception, another exception occurred:

Traceback (most recent call last):
  File "/home/ec2-user/venv_Grupo01/local/lib/python3.6/site-packages/urllib3/connectionpool.py", line 603, in urlopen
    chunked=chunked)
  File "/home/ec2-user/venv_Grupo01/local/lib/python3.6/site-packages/urllib3/connectionpool.py", line 355, in _make_request
    conn.request(method, url, **httplib_request_kw)
  File "/usr/lib64/python3.6/http/client.py", line 1254, in request
    self._send_request(method, url, body, headers, encode_chunked)
  File "/usr/lib64/python3.6/http/client.py", line 1300, in _send_request
    self.endheaders(body, encode_chunked=encode_chunked)
  File "/usr/lib64/python3.6/http/client.py", line 1249, in endheaders
    self._send_output(message_body, encode_chunked=encode_chunked)
  File "/usr/lib64/python3.6/http/client.py", line 1036, in _send_output
    self.send(msg)
  File "/usr/lib64/python3.6/http/client.py", line 974, in send
    self.connect()
  File "/home/ec2-user/venv_Grupo01/local/lib/python3.6/site-packages/urllib3/connection.py", line 183, in connect
    conn = self._new_conn()
  File "/home/ec2-user/venv_Grupo01/local/lib/python3.6/site-packages/urllib3/connection.py", line 169, in _new_conn
    self, "Failed to establish a new connection: %s" % e)
urllib3.exceptions.NewConnectionError: <urllib3.connection.HTTPConnection object at 0x7f3308482dd8>: Failed to establish a new connection: [Errno 110] Connection timed out

During handling of the above exception, another exception occurred:

Traceback (most recent call last):
  File "/home/ec2-user/venv_Grupo01/local/lib/python3.6/site-packages/requests/adapters.py", line 449, in send
    timeout=timeout
  File "/home/ec2-user/venv_Grupo01/local/lib/python3.6/site-packages/urllib3/connectionpool.py", line 641, in urlopen
    _stacktrace=sys.exc_info()[2])
  File "/home/ec2-user/venv_Grupo01/local/lib/python3.6/site-packages/urllib3/util/retry.py", line 399, in increment
    raise MaxRetryError(_pool, url, error or ResponseError(cause))
urllib3.exceptions.MaxRetryError: HTTPConnectionPool(host='54.235.13.161', port=8000): Max retries exceeded with url: /disenos/ (Caused by NewConnectionError('<urllib3.connection.HTTPConnection object at 0x7f3308482dd8>: Failed to establish a new connection: [Errno 110] Connection timed out',))

During handling of the above exception, another exception occurred:

Traceback (most recent call last):
  File "/home/ec2-user/Grupo01/image_process.py", line 17, in <module>
    response = requests.get(url)
  File "/home/ec2-user/venv_Grupo01/local/lib/python3.6/site-packages/requests/api.py", line 75, in get
    return request('get', url, params=params, **kwargs)
  File "/home/ec2-user/venv_Grupo01/local/lib/python3.6/site-packages/requests/api.py", line 60, in request
    return session.request(method=method, url=url, **kwargs)
  File "/home/ec2-user/venv_Grupo01/local/lib/python3.6/site-packages/requests/sessions.py", line 533, in request
    resp = self.send(prep, **send_kwargs)
  File "/home/ec2-user/venv_Grupo01/local/lib/python3.6/site-packages/requests/sessions.py", line 646, in send
    r = adapter.send(request, **kwargs)
  File "/home/ec2-user/venv_Grupo01/local/lib/python3.6/site-packages/requests/adapters.py", line 516, in send
    raise ConnectionError(e, request=request)
requests.exceptions.ConnectionError: HTTPConnectionPool(host='54.235.13.161', port=8000): Max retries exceeded with url: /disenos/ (Caused by NewConnectionError('<urllib3.connection.HTTPConnection object at 0x7f3308482dd8>: Failed to establish a new connection: [Errno 110] Connection timed out',))
Traceback (most recent call last):
  File "/home/ec2-user/Grupo01/image_process.py", line 20, in <module>
    f = open(settings.BASE_DIR + "/logs/log", "a+")
FileNotFoundError: [Errno 2] No such file or directory: '/home/ec2-user/Grupo01/logs/log'
Traceback (most recent call last):
  File "/home/ec2-user/venv_Grupo01/local/lib/python3.6/site-packages/urllib3/connection.py", line 160, in _new_conn
    (self._dns_host, self.port), self.timeout, **extra_kw)
  File "/home/ec2-user/venv_Grupo01/local/lib/python3.6/site-packages/urllib3/util/connection.py", line 80, in create_connection
    raise err
  File "/home/ec2-user/venv_Grupo01/local/lib/python3.6/site-packages/urllib3/util/connection.py", line 70, in create_connection
    sock.connect(sa)
TimeoutError: [Errno 110] Connection timed out

During handling of the above exception, another exception occurred:

Traceback (most recent call last):
  File "/home/ec2-user/venv_Grupo01/local/lib/python3.6/site-packages/urllib3/connectionpool.py", line 603, in urlopen
    chunked=chunked)
  File "/home/ec2-user/venv_Grupo01/local/lib/python3.6/site-packages/urllib3/connectionpool.py", line 355, in _make_request
    conn.request(method, url, **httplib_request_kw)
  File "/usr/lib64/python3.6/http/client.py", line 1254, in request
    self._send_request(method, url, body, headers, encode_chunked)
  File "/usr/lib64/python3.6/http/client.py", line 1300, in _send_request
    self.endheaders(body, encode_chunked=encode_chunked)
  File "/usr/lib64/python3.6/http/client.py", line 1249, in endheaders
    self._send_output(message_body, encode_chunked=encode_chunked)
  File "/usr/lib64/python3.6/http/client.py", line 1036, in _send_output
    self.send(msg)
  File "/usr/lib64/python3.6/http/client.py", line 974, in send
    self.connect()
  File "/home/ec2-user/venv_Grupo01/local/lib/python3.6/site-packages/urllib3/connection.py", line 183, in connect
    conn = self._new_conn()
  File "/home/ec2-user/venv_Grupo01/local/lib/python3.6/site-packages/urllib3/connection.py", line 169, in _new_conn
    self, "Failed to establish a new connection: %s" % e)
urllib3.exceptions.NewConnectionError: <urllib3.connection.HTTPConnection object at 0x7f9a4fa2cdd8>: Failed to establish a new connection: [Errno 110] Connection timed out

During handling of the above exception, another exception occurred:

Traceback (most recent call last):
  File "/home/ec2-user/venv_Grupo01/local/lib/python3.6/site-packages/requests/adapters.py", line 449, in send
    timeout=timeout
  File "/home/ec2-user/venv_Grupo01/local/lib/python3.6/site-packages/urllib3/connectionpool.py", line 641, in urlopen
    _stacktrace=sys.exc_info()[2])
  File "/home/ec2-user/venv_Grupo01/local/lib/python3.6/site-packages/urllib3/util/retry.py", line 399, in increment
    raise MaxRetryError(_pool, url, error or ResponseError(cause))
urllib3.exceptions.MaxRetryError: HTTPConnectionPool(host='54.235.13.161', port=8000): Max retries exceeded with url: /disenos/ (Caused by NewConnectionError('<urllib3.connection.HTTPConnection object at 0x7f9a4fa2cdd8>: Failed to establish a new connection: [Errno 110] Connection timed out',))

During handling of the above exception, another exception occurred:

Traceback (most recent call last):
  File "/home/ec2-user/Grupo01/image_process.py", line 17, in <module>
    response = requests.get(url)
  File "/home/ec2-user/venv_Grupo01/local/lib/python3.6/site-packages/requests/api.py", line 75, in get
    return request('get', url, params=params, **kwargs)
  File "/home/ec2-user/venv_Grupo01/local/lib/python3.6/site-packages/requests/api.py", line 60, in request
    return session.request(method=method, url=url, **kwargs)
  File "/home/ec2-user/venv_Grupo01/local/lib/python3.6/site-packages/requests/sessions.py", line 533, in request
    resp = self.send(prep, **send_kwargs)
  File "/home/ec2-user/venv_Grupo01/local/lib/python3.6/site-packages/requests/sessions.py", line 646, in send
    r = adapter.send(request, **kwargs)
  File "/home/ec2-user/venv_Grupo01/local/lib/python3.6/site-packages/requests/adapters.py", line 516, in send
    raise ConnectionError(e, request=request)
requests.exceptions.ConnectionError: HTTPConnectionPool(host='54.235.13.161', port=8000): Max retries exceeded with url: /disenos/ (Caused by NewConnectionError('<urllib3.connection.HTTPConnection object at 0x7f9a4fa2cdd8>: Failed to establish a new connection: [Errno 110] Connection timed out',))
Traceback (most recent call last):
  File "/home/ec2-user/venv_Grupo01/local/lib/python3.6/site-packages/urllib3/connection.py", line 160, in _new_conn
    (self._dns_host, self.port), self.timeout, **extra_kw)
  File "/home/ec2-user/venv_Grupo01/local/lib/python3.6/site-packages/urllib3/util/connection.py", line 80, in create_connection
    raise err
  File "/home/ec2-user/venv_Grupo01/local/lib/python3.6/site-packages/urllib3/util/connection.py", line 70, in create_connection
    sock.connect(sa)
TimeoutError: [Errno 110] Connection timed out

During handling of the above exception, another exception occurred:

Traceback (most recent call last):
  File "/home/ec2-user/venv_Grupo01/local/lib/python3.6/site-packages/urllib3/connectionpool.py", line 603, in urlopen
    chunked=chunked)
  File "/home/ec2-user/venv_Grupo01/local/lib/python3.6/site-packages/urllib3/connectionpool.py", line 355, in _make_request
    conn.request(method, url, **httplib_request_kw)
  File "/usr/lib64/python3.6/http/client.py", line 1254, in request
    self._send_request(method, url, body, headers, encode_chunked)
  File "/usr/lib64/python3.6/http/client.py", line 1300, in _send_request
    self.endheaders(body, encode_chunked=encode_chunked)
  File "/usr/lib64/python3.6/http/client.py", line 1249, in endheaders
    self._send_output(message_body, encode_chunked=encode_chunked)
  File "/usr/lib64/python3.6/http/client.py", line 1036, in _send_output
    self.send(msg)
  File "/usr/lib64/python3.6/http/client.py", line 974, in send
    self.connect()
  File "/home/ec2-user/venv_Grupo01/local/lib/python3.6/site-packages/urllib3/connection.py", line 183, in connect
    conn = self._new_conn()
  File "/home/ec2-user/venv_Grupo01/local/lib/python3.6/site-packages/urllib3/connection.py", line 169, in _new_conn
    self, "Failed to establish a new connection: %s" % e)
urllib3.exceptions.NewConnectionError: <urllib3.connection.HTTPConnection object at 0x7f8cf807ed68>: Failed to establish a new connection: [Errno 110] Connection timed out

During handling of the above exception, another exception occurred:

Traceback (most recent call last):
  File "/home/ec2-user/venv_Grupo01/local/lib/python3.6/site-packages/requests/adapters.py", line 449, in send
    timeout=timeout
  File "/home/ec2-user/venv_Grupo01/local/lib/python3.6/site-packages/urllib3/connectionpool.py", line 641, in urlopen
    _stacktrace=sys.exc_info()[2])
  File "/home/ec2-user/venv_Grupo01/local/lib/python3.6/site-packages/urllib3/util/retry.py", line 399, in increment
    raise MaxRetryError(_pool, url, error or ResponseError(cause))
urllib3.exceptions.MaxRetryError: HTTPConnectionPool(host='54.235.13.161', port=8000): Max retries exceeded with url: /disenos/ (Caused by NewConnectionError('<urllib3.connection.HTTPConnection object at 0x7f8cf807ed68>: Failed to establish a new connection: [Errno 110] Connection timed out',))

During handling of the above exception, another exception occurred:

Traceback (most recent call last):
  File "/home/ec2-user/Grupo01/image_process.py", line 17, in <module>
    response = requests.get(url)
  File "/home/ec2-user/venv_Grupo01/local/lib/python3.6/site-packages/requests/api.py", line 75, in get
    return request('get', url, params=params, **kwargs)
  File "/home/ec2-user/venv_Grupo01/local/lib/python3.6/site-packages/requests/api.py", line 60, in request
    return session.request(method=method, url=url, **kwargs)
  File "/home/ec2-user/venv_Grupo01/local/lib/python3.6/site-packages/requests/sessions.py", line 533, in request
    resp = self.send(prep, **send_kwargs)
  File "/home/ec2-user/venv_Grupo01/local/lib/python3.6/site-packages/requests/sessions.py", line 646, in send
    r = adapter.send(request, **kwargs)
  File "/home/ec2-user/venv_Grupo01/local/lib/python3.6/site-packages/requests/adapters.py", line 516, in send
    raise ConnectionError(e, request=request)
requests.exceptions.ConnectionError: HTTPConnectionPool(host='54.235.13.161', port=8000): Max retries exceeded with url: /disenos/ (Caused by NewConnectionError('<urllib3.connection.HTTPConnection object at 0x7f8cf807ed68>: Failed to establish a new connection: [Errno 110] Connection timed out',))
imagen-consciencia_PJvYBD22019-09-1600-51-02-189
Traceback (most recent call last):
  File "/home/ec2-user/venv_Grupo01/local/lib/python3.6/site-packages/urllib3/connection.py", line 160, in _new_conn
    (self._dns_host, self.port), self.timeout, **extra_kw)
  File "/home/ec2-user/venv_Grupo01/local/lib/python3.6/site-packages/urllib3/util/connection.py", line 80, in create_connection
    raise err
  File "/home/ec2-user/venv_Grupo01/local/lib/python3.6/site-packages/urllib3/util/connection.py", line 70, in create_connection
    sock.connect(sa)
ConnectionRefusedError: [Errno 111] Connection refused

During handling of the above exception, another exception occurred:

Traceback (most recent call last):
  File "/home/ec2-user/venv_Grupo01/local/lib/python3.6/site-packages/urllib3/connectionpool.py", line 603, in urlopen
    chunked=chunked)
  File "/home/ec2-user/venv_Grupo01/local/lib/python3.6/site-packages/urllib3/connectionpool.py", line 355, in _make_request
    conn.request(method, url, **httplib_request_kw)
  File "/usr/lib64/python3.6/http/client.py", line 1254, in request
    self._send_request(method, url, body, headers, encode_chunked)
  File "/usr/lib64/python3.6/http/client.py", line 1300, in _send_request
    self.endheaders(body, encode_chunked=encode_chunked)
  File "/usr/lib64/python3.6/http/client.py", line 1249, in endheaders
    self._send_output(message_body, encode_chunked=encode_chunked)
  File "/usr/lib64/python3.6/http/client.py", line 1036, in _send_output
    self.send(msg)
  File "/usr/lib64/python3.6/http/client.py", line 974, in send
    self.connect()
  File "/home/ec2-user/venv_Grupo01/local/lib/python3.6/site-packages/urllib3/connection.py", line 183, in connect
    conn = self._new_conn()
  File "/home/ec2-user/venv_Grupo01/local/lib/python3.6/site-packages/urllib3/connection.py", line 169, in _new_conn
    self, "Failed to establish a new connection: %s" % e)
urllib3.exceptions.NewConnectionError: <urllib3.connection.HTTPConnection object at 0x7fe7f3c04e10>: Failed to establish a new connection: [Errno 111] Connection refused

During handling of the above exception, another exception occurred:

Traceback (most recent call last):
  File "/home/ec2-user/venv_Grupo01/local/lib/python3.6/site-packages/requests/adapters.py", line 449, in send
    timeout=timeout
  File "/home/ec2-user/venv_Grupo01/local/lib/python3.6/site-packages/urllib3/connectionpool.py", line 641, in urlopen
    _stacktrace=sys.exc_info()[2])
  File "/home/ec2-user/venv_Grupo01/local/lib/python3.6/site-packages/urllib3/util/retry.py", line 399, in increment
    raise MaxRetryError(_pool, url, error or ResponseError(cause))
urllib3.exceptions.MaxRetryError: HTTPConnectionPool(host='54.174.167.225', port=8080): Max retries exceeded with url: /disenos/ (Caused by NewConnectionError('<urllib3.connection.HTTPConnection object at 0x7fe7f3c04e10>: Failed to establish a new connection: [Errno 111] Connection refused',))

During handling of the above exception, another exception occurred:

Traceback (most recent call last):
  File "/home/ec2-user/Grupo01/image_process.py", line 17, in <module>
    response = requests.get(url)
  File "/home/ec2-user/venv_Grupo01/local/lib/python3.6/site-packages/requests/api.py", line 75, in get
    return request('get', url, params=params, **kwargs)
  File "/home/ec2-user/venv_Grupo01/local/lib/python3.6/site-packages/requests/api.py", line 60, in request
    return session.request(method=method, url=url, **kwargs)
  File "/home/ec2-user/venv_Grupo01/local/lib/python3.6/site-packages/requests/sessions.py", line 533, in request
    resp = self.send(prep, **send_kwargs)
  File "/home/ec2-user/venv_Grupo01/local/lib/python3.6/site-packages/requests/sessions.py", line 646, in send
    r = adapter.send(request, **kwargs)
  File "/home/ec2-user/venv_Grupo01/local/lib/python3.6/site-packages/requests/adapters.py", line 516, in send
    raise ConnectionError(e, request=request)
requests.exceptions.ConnectionError: HTTPConnectionPool(host='54.174.167.225', port=8080): Max retries exceeded with url: /disenos/ (Caused by NewConnectionError('<urllib3.connection.HTTPConnection object at 0x7fe7f3c04e10>: Failed to establish a new connection: [Errno 111] Connection refused',))
Traceback (most recent call last):
  File "/home/ec2-user/venv_Grupo01/local/lib/python3.6/site-packages/urllib3/connection.py", line 160, in _new_conn
    (self._dns_host, self.port), self.timeout, **extra_kw)
  File "/home/ec2-user/venv_Grupo01/local/lib/python3.6/site-packages/urllib3/util/connection.py", line 80, in create_connection
    raise err
  File "/home/ec2-user/venv_Grupo01/local/lib/python3.6/site-packages/urllib3/util/connection.py", line 70, in create_connection
    sock.connect(sa)
ConnectionRefusedError: [Errno 111] Connection refused

During handling of the above exception, another exception occurred:

Traceback (most recent call last):
  File "/home/ec2-user/venv_Grupo01/local/lib/python3.6/site-packages/urllib3/connectionpool.py", line 603, in urlopen
    chunked=chunked)
  File "/home/ec2-user/venv_Grupo01/local/lib/python3.6/site-packages/urllib3/connectionpool.py", line 355, in _make_request
    conn.request(method, url, **httplib_request_kw)
  File "/usr/lib64/python3.6/http/client.py", line 1254, in request
    self._send_request(method, url, body, headers, encode_chunked)
  File "/usr/lib64/python3.6/http/client.py", line 1300, in _send_request
    self.endheaders(body, encode_chunked=encode_chunked)
  File "/usr/lib64/python3.6/http/client.py", line 1249, in endheaders
    self._send_output(message_body, encode_chunked=encode_chunked)
  File "/usr/lib64/python3.6/http/client.py", line 1036, in _send_output
    self.send(msg)
  File "/usr/lib64/python3.6/http/client.py", line 974, in send
    self.connect()
  File "/home/ec2-user/venv_Grupo01/local/lib/python3.6/site-packages/urllib3/connection.py", line 183, in connect
    conn = self._new_conn()
  File "/home/ec2-user/venv_Grupo01/local/lib/python3.6/site-packages/urllib3/connection.py", line 169, in _new_conn
    self, "Failed to establish a new connection: %s" % e)
urllib3.exceptions.NewConnectionError: <urllib3.connection.HTTPConnection object at 0x7fe33fc1be10>: Failed to establish a new connection: [Errno 111] Connection refused

During handling of the above exception, another exception occurred:

Traceback (most recent call last):
  File "/home/ec2-user/venv_Grupo01/local/lib/python3.6/site-packages/requests/adapters.py", line 449, in send
    timeout=timeout
  File "/home/ec2-user/venv_Grupo01/local/lib/python3.6/site-packages/urllib3/connectionpool.py", line 641, in urlopen
    _stacktrace=sys.exc_info()[2])
  File "/home/ec2-user/venv_Grupo01/local/lib/python3.6/site-packages/urllib3/util/retry.py", line 399, in increment
    raise MaxRetryError(_pool, url, error or ResponseError(cause))
urllib3.exceptions.MaxRetryError: HTTPConnectionPool(host='54.174.167.225', port=8080): Max retries exceeded with url: /disenos/ (Caused by NewConnectionError('<urllib3.connection.HTTPConnection object at 0x7fe33fc1be10>: Failed to establish a new connection: [Errno 111] Connection refused',))

During handling of the above exception, another exception occurred:

Traceback (most recent call last):
  File "/home/ec2-user/Grupo01/image_process.py", line 17, in <module>
    response = requests.get(url)
  File "/home/ec2-user/venv_Grupo01/local/lib/python3.6/site-packages/requests/api.py", line 75, in get
    return request('get', url, params=params, **kwargs)
  File "/home/ec2-user/venv_Grupo01/local/lib/python3.6/site-packages/requests/api.py", line 60, in request
    return session.request(method=method, url=url, **kwargs)
  File "/home/ec2-user/venv_Grupo01/local/lib/python3.6/site-packages/requests/sessions.py", line 533, in request
    resp = self.send(prep, **send_kwargs)
  File "/home/ec2-user/venv_Grupo01/local/lib/python3.6/site-packages/requests/sessions.py", line 646, in send
    r = adapter.send(request, **kwargs)
  File "/home/ec2-user/venv_Grupo01/local/lib/python3.6/site-packages/requests/adapters.py", line 516, in send
    raise ConnectionError(e, request=request)
requests.exceptions.ConnectionError: HTTPConnectionPool(host='54.174.167.225', port=8080): Max retries exceeded with url: /disenos/ (Caused by NewConnectionError('<urllib3.connection.HTTPConnection object at 0x7fe33fc1be10>: Failed to establish a new connection: [Errno 111] Connection refused',))
Traceback (most recent call last):
  File "/home/ec2-user/venv_Grupo01/local/lib/python3.6/site-packages/urllib3/connection.py", line 160, in _new_conn
    (self._dns_host, self.port), self.timeout, **extra_kw)
  File "/home/ec2-user/venv_Grupo01/local/lib/python3.6/site-packages/urllib3/util/connection.py", line 80, in create_connection
    raise err
  File "/home/ec2-user/venv_Grupo01/local/lib/python3.6/site-packages/urllib3/util/connection.py", line 70, in create_connection
    sock.connect(sa)
ConnectionRefusedError: [Errno 111] Connection refused

During handling of the above exception, another exception occurred:

Traceback (most recent call last):
  File "/home/ec2-user/venv_Grupo01/local/lib/python3.6/site-packages/urllib3/connectionpool.py", line 603, in urlopen
    chunked=chunked)
  File "/home/ec2-user/venv_Grupo01/local/lib/python3.6/site-packages/urllib3/connectionpool.py", line 355, in _make_request
    conn.request(method, url, **httplib_request_kw)
  File "/usr/lib64/python3.6/http/client.py", line 1254, in request
    self._send_request(method, url, body, headers, encode_chunked)
  File "/usr/lib64/python3.6/http/client.py", line 1300, in _send_request
    self.endheaders(body, encode_chunked=encode_chunked)
  File "/usr/lib64/python3.6/http/client.py", line 1249, in endheaders
    self._send_output(message_body, encode_chunked=encode_chunked)
  File "/usr/lib64/python3.6/http/client.py", line 1036, in _send_output
    self.send(msg)
  File "/usr/lib64/python3.6/http/client.py", line 974, in send
    self.connect()
  File "/home/ec2-user/venv_Grupo01/local/lib/python3.6/site-packages/urllib3/connection.py", line 183, in connect
    conn = self._new_conn()
  File "/home/ec2-user/venv_Grupo01/local/lib/python3.6/site-packages/urllib3/connection.py", line 169, in _new_conn
    self, "Failed to establish a new connection: %s" % e)
urllib3.exceptions.NewConnectionError: <urllib3.connection.HTTPConnection object at 0x7fa540076da0>: Failed to establish a new connection: [Errno 111] Connection refused

During handling of the above exception, another exception occurred:

Traceback (most recent call last):
  File "/home/ec2-user/venv_Grupo01/local/lib/python3.6/site-packages/requests/adapters.py", line 449, in send
    timeout=timeout
  File "/home/ec2-user/venv_Grupo01/local/lib/python3.6/site-packages/urllib3/connectionpool.py", line 641, in urlopen
    _stacktrace=sys.exc_info()[2])
  File "/home/ec2-user/venv_Grupo01/local/lib/python3.6/site-packages/urllib3/util/retry.py", line 399, in increment
    raise MaxRetryError(_pool, url, error or ResponseError(cause))
urllib3.exceptions.MaxRetryError: HTTPConnectionPool(host='54.174.167.225', port=8080): Max retries exceeded with url: /disenos/ (Caused by NewConnectionError('<urllib3.connection.HTTPConnection object at 0x7fa540076da0>: Failed to establish a new connection: [Errno 111] Connection refused',))

During handling of the above exception, another exception occurred:

Traceback (most recent call last):
  File "/home/ec2-user/Grupo01/image_process.py", line 17, in <module>
    response = requests.get(url)
  File "/home/ec2-user/venv_Grupo01/local/lib/python3.6/site-packages/requests/api.py", line 75, in get
    return request('get', url, params=params, **kwargs)
  File "/home/ec2-user/venv_Grupo01/local/lib/python3.6/site-packages/requests/api.py", line 60, in request
    return session.request(method=method, url=url, **kwargs)
  File "/home/ec2-user/venv_Grupo01/local/lib/python3.6/site-packages/requests/sessions.py", line 533, in request
    resp = self.send(prep, **send_kwargs)
  File "/home/ec2-user/venv_Grupo01/local/lib/python3.6/site-packages/requests/sessions.py", line 646, in send
    r = adapter.send(request, **kwargs)
  File "/home/ec2-user/venv_Grupo01/local/lib/python3.6/site-packages/requests/adapters.py", line 516, in send
    raise ConnectionError(e, request=request)
requests.exceptions.ConnectionError: HTTPConnectionPool(host='54.174.167.225', port=8080): Max retries exceeded with url: /disenos/ (Caused by NewConnectionError('<urllib3.connection.HTTPConnection object at 0x7fa540076da0>: Failed to establish a new connection: [Errno 111] Connection refused',))
Traceback (most recent call last):
  File "/home/ec2-user/venv_Grupo01/local/lib/python3.6/site-packages/urllib3/connection.py", line 160, in _new_conn
    (self._dns_host, self.port), self.timeout, **extra_kw)
  File "/home/ec2-user/venv_Grupo01/local/lib/python3.6/site-packages/urllib3/util/connection.py", line 80, in create_connection
    raise err
  File "/home/ec2-user/venv_Grupo01/local/lib/python3.6/site-packages/urllib3/util/connection.py", line 70, in create_connection
    sock.connect(sa)
ConnectionRefusedError: [Errno 111] Connection refused

During handling of the above exception, another exception occurred:

Traceback (most recent call last):
  File "/home/ec2-user/venv_Grupo01/local/lib/python3.6/site-packages/urllib3/connectionpool.py", line 603, in urlopen
    chunked=chunked)
  File "/home/ec2-user/venv_Grupo01/local/lib/python3.6/site-packages/urllib3/connectionpool.py", line 355, in _make_request
    conn.request(method, url, **httplib_request_kw)
  File "/usr/lib64/python3.6/http/client.py", line 1254, in request
    self._send_request(method, url, body, headers, encode_chunked)
  File "/usr/lib64/python3.6/http/client.py", line 1300, in _send_request
    self.endheaders(body, encode_chunked=encode_chunked)
  File "/usr/lib64/python3.6/http/client.py", line 1249, in endheaders
    self._send_output(message_body, encode_chunked=encode_chunked)
  File "/usr/lib64/python3.6/http/client.py", line 1036, in _send_output
    self.send(msg)
  File "/usr/lib64/python3.6/http/client.py", line 974, in send
    self.connect()
  File "/home/ec2-user/venv_Grupo01/local/lib/python3.6/site-packages/urllib3/connection.py", line 183, in connect
    conn = self._new_conn()
  File "/home/ec2-user/venv_Grupo01/local/lib/python3.6/site-packages/urllib3/connection.py", line 169, in _new_conn
    self, "Failed to establish a new connection: %s" % e)
urllib3.exceptions.NewConnectionError: <urllib3.connection.HTTPConnection object at 0x7f074812ae10>: Failed to establish a new connection: [Errno 111] Connection refused

During handling of the above exception, another exception occurred:

Traceback (most recent call last):
  File "/home/ec2-user/venv_Grupo01/local/lib/python3.6/site-packages/requests/adapters.py", line 449, in send
    timeout=timeout
  File "/home/ec2-user/venv_Grupo01/local/lib/python3.6/site-packages/urllib3/connectionpool.py", line 641, in urlopen
    _stacktrace=sys.exc_info()[2])
  File "/home/ec2-user/venv_Grupo01/local/lib/python3.6/site-packages/urllib3/util/retry.py", line 399, in increment
    raise MaxRetryError(_pool, url, error or ResponseError(cause))
urllib3.exceptions.MaxRetryError: HTTPConnectionPool(host='54.174.167.225', port=8080): Max retries exceeded with url: /disenos/ (Caused by NewConnectionError('<urllib3.connection.HTTPConnection object at 0x7f074812ae10>: Failed to establish a new connection: [Errno 111] Connection refused',))

During handling of the above exception, another exception occurred:

Traceback (most recent call last):
  File "/home/ec2-user/Grupo01/image_process.py", line 17, in <module>
    response = requests.get(url)
  File "/home/ec2-user/venv_Grupo01/local/lib/python3.6/site-packages/requests/api.py", line 75, in get
    return request('get', url, params=params, **kwargs)
  File "/home/ec2-user/venv_Grupo01/local/lib/python3.6/site-packages/requests/api.py", line 60, in request
    return session.request(method=method, url=url, **kwargs)
  File "/home/ec2-user/venv_Grupo01/local/lib/python3.6/site-packages/requests/sessions.py", line 533, in request
    resp = self.send(prep, **send_kwargs)
  File "/home/ec2-user/venv_Grupo01/local/lib/python3.6/site-packages/requests/sessions.py", line 646, in send
    r = adapter.send(request, **kwargs)
  File "/home/ec2-user/venv_Grupo01/local/lib/python3.6/site-packages/requests/adapters.py", line 516, in send
    raise ConnectionError(e, request=request)
requests.exceptions.ConnectionError: HTTPConnectionPool(host='54.174.167.225', port=8080): Max retries exceeded with url: /disenos/ (Caused by NewConnectionError('<urllib3.connection.HTTPConnection object at 0x7f074812ae10>: Failed to establish a new connection: [Errno 111] Connection refused',))
Traceback (most recent call last):
  File "/home/ec2-user/venv_Grupo01/local/lib/python3.6/site-packages/urllib3/connection.py", line 160, in _new_conn
    (self._dns_host, self.port), self.timeout, **extra_kw)
  File "/home/ec2-user/venv_Grupo01/local/lib/python3.6/site-packages/urllib3/util/connection.py", line 80, in create_connection
    raise err
  File "/home/ec2-user/venv_Grupo01/local/lib/python3.6/site-packages/urllib3/util/connection.py", line 70, in create_connection
    sock.connect(sa)
ConnectionRefusedError: [Errno 111] Connection refused

During handling of the above exception, another exception occurred:

Traceback (most recent call last):
  File "/home/ec2-user/venv_Grupo01/local/lib/python3.6/site-packages/urllib3/connectionpool.py", line 603, in urlopen
    chunked=chunked)
  File "/home/ec2-user/venv_Grupo01/local/lib/python3.6/site-packages/urllib3/connectionpool.py", line 355, in _make_request
    conn.request(method, url, **httplib_request_kw)
  File "/usr/lib64/python3.6/http/client.py", line 1254, in request
    self._send_request(method, url, body, headers, encode_chunked)
  File "/usr/lib64/python3.6/http/client.py", line 1300, in _send_request
    self.endheaders(body, encode_chunked=encode_chunked)
  File "/usr/lib64/python3.6/http/client.py", line 1249, in endheaders
    self._send_output(message_body, encode_chunked=encode_chunked)
  File "/usr/lib64/python3.6/http/client.py", line 1036, in _send_output
    self.send(msg)
  File "/usr/lib64/python3.6/http/client.py", line 974, in send
    self.connect()
  File "/home/ec2-user/venv_Grupo01/local/lib/python3.6/site-packages/urllib3/connection.py", line 183, in connect
    conn = self._new_conn()
  File "/home/ec2-user/venv_Grupo01/local/lib/python3.6/site-packages/urllib3/connection.py", line 169, in _new_conn
    self, "Failed to establish a new connection: %s" % e)
urllib3.exceptions.NewConnectionError: <urllib3.connection.HTTPConnection object at 0x7efde9bfee10>: Failed to establish a new connection: [Errno 111] Connection refused

During handling of the above exception, another exception occurred:

Traceback (most recent call last):
  File "/home/ec2-user/venv_Grupo01/local/lib/python3.6/site-packages/requests/adapters.py", line 449, in send
    timeout=timeout
  File "/home/ec2-user/venv_Grupo01/local/lib/python3.6/site-packages/urllib3/connectionpool.py", line 641, in urlopen
    _stacktrace=sys.exc_info()[2])
  File "/home/ec2-user/venv_Grupo01/local/lib/python3.6/site-packages/urllib3/util/retry.py", line 399, in increment
    raise MaxRetryError(_pool, url, error or ResponseError(cause))
urllib3.exceptions.MaxRetryError: HTTPConnectionPool(host='54.174.167.225', port=8080): Max retries exceeded with url: /disenos/ (Caused by NewConnectionError('<urllib3.connection.HTTPConnection object at 0x7efde9bfee10>: Failed to establish a new connection: [Errno 111] Connection refused',))

During handling of the above exception, another exception occurred:

Traceback (most recent call last):
  File "/home/ec2-user/Grupo01/image_process.py", line 17, in <module>
    response = requests.get(url)
  File "/home/ec2-user/venv_Grupo01/local/lib/python3.6/site-packages/requests/api.py", line 75, in get
    return request('get', url, params=params, **kwargs)
  File "/home/ec2-user/venv_Grupo01/local/lib/python3.6/site-packages/requests/api.py", line 60, in request
    return session.request(method=method, url=url, **kwargs)
  File "/home/ec2-user/venv_Grupo01/local/lib/python3.6/site-packages/requests/sessions.py", line 533, in request
    resp = self.send(prep, **send_kwargs)
  File "/home/ec2-user/venv_Grupo01/local/lib/python3.6/site-packages/requests/sessions.py", line 646, in send
    r = adapter.send(request, **kwargs)
  File "/home/ec2-user/venv_Grupo01/local/lib/python3.6/site-packages/requests/adapters.py", line 516, in send
    raise ConnectionError(e, request=request)
requests.exceptions.ConnectionError: HTTPConnectionPool(host='54.174.167.225', port=8080): Max retries exceeded with url: /disenos/ (Caused by NewConnectionError('<urllib3.connection.HTTPConnection object at 0x7efde9bfee10>: Failed to establish a new connection: [Errno 111] Connection refused',))
Traceback (most recent call last):
  File "/home/ec2-user/venv_Grupo01/local/lib/python3.6/site-packages/urllib3/connection.py", line 160, in _new_conn
    (self._dns_host, self.port), self.timeout, **extra_kw)
  File "/home/ec2-user/venv_Grupo01/local/lib/python3.6/site-packages/urllib3/util/connection.py", line 80, in create_connection
    raise err
  File "/home/ec2-user/venv_Grupo01/local/lib/python3.6/site-packages/urllib3/util/connection.py", line 70, in create_connection
    sock.connect(sa)
ConnectionRefusedError: [Errno 111] Connection refused

During handling of the above exception, another exception occurred:

Traceback (most recent call last):
  File "/home/ec2-user/venv_Grupo01/local/lib/python3.6/site-packages/urllib3/connectionpool.py", line 603, in urlopen
    chunked=chunked)
  File "/home/ec2-user/venv_Grupo01/local/lib/python3.6/site-packages/urllib3/connectionpool.py", line 355, in _make_request
    conn.request(method, url, **httplib_request_kw)
  File "/usr/lib64/python3.6/http/client.py", line 1254, in request
    self._send_request(method, url, body, headers, encode_chunked)
  File "/usr/lib64/python3.6/http/client.py", line 1300, in _send_request
    self.endheaders(body, encode_chunked=encode_chunked)
  File "/usr/lib64/python3.6/http/client.py", line 1249, in endheaders
    self._send_output(message_body, encode_chunked=encode_chunked)
  File "/usr/lib64/python3.6/http/client.py", line 1036, in _send_output
    self.send(msg)
  File "/usr/lib64/python3.6/http/client.py", line 974, in send
    self.connect()
  File "/home/ec2-user/venv_Grupo01/local/lib/python3.6/site-packages/urllib3/connection.py", line 183, in connect
    conn = self._new_conn()
  File "/home/ec2-user/venv_Grupo01/local/lib/python3.6/site-packages/urllib3/connection.py", line 169, in _new_conn
    self, "Failed to establish a new connection: %s" % e)
urllib3.exceptions.NewConnectionError: <urllib3.connection.HTTPConnection object at 0x7faf4d047e10>: Failed to establish a new connection: [Errno 111] Connection refused

During handling of the above exception, another exception occurred:

Traceback (most recent call last):
  File "/home/ec2-user/venv_Grupo01/local/lib/python3.6/site-packages/requests/adapters.py", line 449, in send
    timeout=timeout
  File "/home/ec2-user/venv_Grupo01/local/lib/python3.6/site-packages/urllib3/connectionpool.py", line 641, in urlopen
    _stacktrace=sys.exc_info()[2])
  File "/home/ec2-user/venv_Grupo01/local/lib/python3.6/site-packages/urllib3/util/retry.py", line 399, in increment
    raise MaxRetryError(_pool, url, error or ResponseError(cause))
urllib3.exceptions.MaxRetryError: HTTPConnectionPool(host='54.174.167.225', port=8080): Max retries exceeded with url: /disenos/ (Caused by NewConnectionError('<urllib3.connection.HTTPConnection object at 0x7faf4d047e10>: Failed to establish a new connection: [Errno 111] Connection refused',))

During handling of the above exception, another exception occurred:

Traceback (most recent call last):
  File "/home/ec2-user/Grupo01/image_process.py", line 17, in <module>
    response = requests.get(url)
  File "/home/ec2-user/venv_Grupo01/local/lib/python3.6/site-packages/requests/api.py", line 75, in get
    return request('get', url, params=params, **kwargs)
  File "/home/ec2-user/venv_Grupo01/local/lib/python3.6/site-packages/requests/api.py", line 60, in request
    return session.request(method=method, url=url, **kwargs)
  File "/home/ec2-user/venv_Grupo01/local/lib/python3.6/site-packages/requests/sessions.py", line 533, in request
    resp = self.send(prep, **send_kwargs)
  File "/home/ec2-user/venv_Grupo01/local/lib/python3.6/site-packages/requests/sessions.py", line 646, in send
    r = adapter.send(request, **kwargs)
  File "/home/ec2-user/venv_Grupo01/local/lib/python3.6/site-packages/requests/adapters.py", line 516, in send
    raise ConnectionError(e, request=request)
requests.exceptions.ConnectionError: HTTPConnectionPool(host='54.174.167.225', port=8080): Max retries exceeded with url: /disenos/ (Caused by NewConnectionError('<urllib3.connection.HTTPConnection object at 0x7faf4d047e10>: Failed to establish a new connection: [Errno 111] Connection refused',))
